<?xml version ="1.0"?> <!-- ประกาศเวอร์ชั่น -->

<robot name = "robot_armm"> <!--ตั้งชื่อ robot -->

<link name = "base_link">
    <visual>
        <geometry>
            <mesh filename="package://robot_description/robot_urdf/robot_base.stl" scale = "0.001 0.001 0.001" />
        </geometry>
        <origin xyz = "-0.35 0.35 0.0" rpy = "1.56 0 0" />
    </visual>

    <collision>
        <geometry>
            <mesh filename ="package://robot_description/robot_urdf/robot_base.stl" scale = "0.001 0.001 0.001"/>
        </geometry>
        <origin xyz = "-0.35 0.35 0.0" rpy = "1.56 0 0" />
    </collision>

     <inertial>
        <origin xyz = "-0.35 0.35 0.0" rpy = "1.56 0 0" />
        <mass value = "0.104"/>
        <inertia ixx = "0.001" ixy = "0" ixz = "0" iyy = "0.001" iyz = "0" izz = "0.001"/>
    </inertial>
</link>

<!-- ////////////    link1    /////////// -->
<link name = "link1">
    <visual>
        <geometry>
            <mesh filename="package://robot_description/robot_urdf/robot_link1.stl" scale = "0.001 0.001 0.001" />
        </geometry>
        <origin xyz = "0.076 0.052 -0.007" rpy = "1.56 3.15 0" />
    </visual>

    <collision>
        <geometry>
            <mesh filename ="package://robot_description/robot_urdf/robot_link1.stl" scale = "0.001 0.001 0.001"/>
        </geometry>
        <origin xyz = "0.076 0.35 0.076" rpy = "1.56 0 0" />
    </collision>

     <inertial>
        <origin xyz = "0.076 0.0 0.076" rpy = "1.56 0 0" />
        <mass value = "0.104"/>
        <inertia ixx = "0.001" ixy = "0" ixz = "0" iyy = "0.001" iyz = "0" izz = "0.001"/>
    </inertial>
</link>

<!-- ////////////    joint1    /////////// -->
<joint name = "joint1" type = "prismatic">

    <parent link = "base_link"/>  
    <child link = "link1"/> 
    <origin xyz = "0 0.3 0.14" rpy = "0 0 0"/> 
    <axis xyz = "1 0 0"/>

    <limit lower = "-0.15" upper = "0.15" effort = "100" velocity = "1"/>
</joint>


<!-- ////////////    link2    /////////// -->
<link name = "link2">
    <visual>
        <geometry>
            <mesh filename="package://robot_description/robot_urdf/robot_link2.stl" scale = "0.001 0.001 0.001" />
        </geometry>
        <origin xyz = "-0.62 -0.075 -0.11" rpy = "1.566 0.0 1.566" />
    </visual>

    <collision>
 
        <geometry>
            <mesh filename ="package://robot_description/robot_urdf/robot_link2.stl" scale = "0.001 0.001 0.001"/>
        </geometry>
        <origin xyz = "-0.35 -0.075 -0.065" rpy = "1.56 0 0" />
    </collision>

     <inertial>
        <origin xyz = "-0.35 -0.075 -0.065" rpy = "1.56 0 0" />
        <mass value = "0.104"/>

        <inertia ixx = "0" ixy = "0" ixz = "0" iyy = "0.001" iyz = "0.0" izz = "0.001"/>
    </inertial>
</link>

<!-- ////////////    joint2    /////////// -->
<joint name = "joint2" type = "prismatic">

    <parent link = "base_link"/>    
    <child link = "link2"/>   
    <origin xyz = "0.27 0 0.14" rpy = "0 0 0"/>  
    <axis xyz = "0 1 0"/>      

    <limit lower = "-0.15" upper = "0.15" effort = "100" velocity = "1"/>
</joint>



</robot>